Workbook

Sheet Invoice Dispute Tracker
A1: Customer | B1: Invoice | C1: Issue (missing PO, incorrect billing, etc.) | D1: Owner | E1: Deadline (max 5 days resolution)

Sheet Ouderdomsanalyseperdebiteur
A1: CodeAdministratie | B1: NaamAdministratie | C1: CodeDebiteur | D1: NaamDebiteur | E1: Code | F1: Boekdatum | G1: Vervaldatum | H1: Factuurnummer | I1: Saldo | J1: Saldo1 | K1: 030dagen | L1: 3160dagen | M1: 6190dagen | N1: 90dagen | O1: Dagenoud | P1: Boekingsstatus
A2: RD1106 | B2: Van Noort Gassler & Co Rotterdam B.V. | C2: 1108 | D2: Van Noort Gassler & Co. 's-Gravenhage B.V. | E2: MEMO | F2: 44833 | G2: 44863 | I2: -22514.97 | J2: -22514.97 | K2: 0 | L2: 0 | M2: 0 | N2: -22514.97 | O2: =TODAY()-G2 -> 1307 | P2: Definitief
A3: RD1106 | B3: Van Noort Gassler & Co Rotterdam B.V. | C3: 1108 | D3: Van Noort Gassler & Co. 's-Gravenhage B.V. | E3: MEMO | F3: 45071 | G3: 45101 | I3: 48698.36 | J3: 48698.36 | K3: 0 | L3: 0 | M3: 0 | N3: 48698.36 | O3: =TODAY()-G3 -> 1069 | P3: Definitief
A4: RD1106 | B4: Van Noort Gassler & Co Rotterdam B.V. | C4: 1108 | D4: Van Noort Gassler & Co. 's-Gravenhage B.V. | E4: VRK | F4: 43690 | G4: 43720 | H4: R190691 | I4: 30.25 | J4: 30.25 | K4: 0 | L4: 0 | M4: 0 | N4: 30.25 | O4: =TODAY()-G4 -> 2450 | P4: Definitief
A5: RD1106 | B5: Van Noort Gassler & Co Rotterdam B.V. | C5: 1108 | D5: Van Noort Gassler & Co. 's-Gravenhage B.V. | E5: VRK | F5: 43690 | G5: 43720 | H5: R190689 | I5: 61.59 | J5: 61.59 | K5: 0 | L5: 0 | M5: 0 | N5: 61.59 | O5: =TODAY()-G5 -> 2450 | P5: Definitief
A6: RD1106 | B6: Van Noort Gassler & Co Rotterdam B.V. | C6: 1108 | D6: Van Noort Gassler & Co. 's-Gravenhage B.V. | E6: VRK | F6: 43690 | G6: 43720 | H6: R190694 | I6: 145.13 | J6: 145.13 | K6: 0 | L6: 0 | M6: 0 | N6: 145.13 | O6: =TODAY()-G6 -> 2450 | P6: Definitief
A7: RD1106 | B7: Van Noort Gassler & Co Rotterdam B.V. | C7: 1108 | D7: Van Noort Gassler & Co. 's-Gravenhage B.V. | E7: VRK | F7: 43735 | G7: 43765 | H7: R190789 | I7: 30.25 | J7: 30.25 | K7: 0 | L7: 0 | M7: 0 | N7: 30.25 | O7: =TODAY()-G7 -> 2405 | P7: Definitief
A8: RD1106 | B8: Van Noort Gassler & Co Rotterdam B.V. | C8: 1108 | D8: Van Noort Gassler & Co. 's-Gravenhage B.V. | E8: VRK | F8: 43735 | G8: 43765 | H8: R190791 | I8: 61.64 | J8: 61.64 | K8: 0 | L8: 0 | M8: 0 | N8: 61.64 | O8: =TODAY()-G8 -> 2405 | P8: Definitief
A9: RD1106 | B9: Van Noort Gassler & Co Rotterdam B.V. | C9: 1108 | D9: Van Noort Gassler & Co. 's-Gravenhage B.V. | E9: VRK | F9: 43735 | G9: 43765 | H9: R190786 | I9: 145.13 | J9: 145.13 | K9: 0 | L9: 0 | M9: 0 | N9: 145.13 | O9: =TODAY()-G9 -> 2405 | P9: Definitief
A10: RD1106 | B10: Van Noort Gassler & Co Rotterdam B.V. | C10: 1108 | D10: Van Noort Gassler & Co. 's-Gravenhage B.V. | E10: VRK | F10: 43774 | G10: 43804 | H10: R190934 | I10: 30.25 | J10: 30.25 | K10: 0 | L10: 0 | M10: 0 | N10: 30.25 | O10: =TODAY()-G10 -> 2366 | P10: Definitief
A11: RD1106 | B11: Van Noort Gassler & Co Rotterdam B.V. | C11: 1108 | D11: Van Noort Gassler & Co. 's-Gravenhage B.V. | E11: VRK | F11: 43774 | G11: 43804 | H11: R190937 | I11: 30.25 | J11: 30.25 | K11: 0 | L11: 0 | M11: 0 | N11: 30.25 | O11: =TODAY()-G11 -> 2366 | P11: Definitief
A12: RD1106 | B12: Van Noort Gassler & Co Rotterdam B.V. | C12: 1108 | D12: Van Noort Gassler & Co. 's-Gravenhage B.V. | E12: VRK | F12: 43774 | G12: 43804 | H12: R190944 | I12: 61.33 | J12: 61.33 | K12: 0 | L12: 0 | M12: 0 | N12: 61.33 | O12: =TODAY()-G12 -> 2366 | P12: Definitief
A13: RD1106 | B13: Van Noort Gassler & Co Rotterdam B.V. | C13: 1108 | D13: Van Noort Gassler & Co. 's-Gravenhage B.V. | E13: VRK | F13: 43774 | G13: 43804 | H13: R190952 | I13: 145.13 | J13: 145.13 | K13: 0 | L13: 0 | M13: 0 | N13: 145.13 | O13: =TODAY()-G13 -> 2366 | P13: Definitief
A14: RD1106 | B14: Van Noort Gassler & Co Rotterdam B.V. | C14: 1108 | D14: Van Noort Gassler & Co. 's-Gravenhage B.V. | E14: VRK | F14: 43774 | G14: 43804 | H14: R190947 | I14: 61.08 | J14: 61.08 | K14: 0 | L14: 0 | M14: 0 | N14: 61.08 | O14: =TODAY()-G14 -> 2366 | P14: Definitief
A15: RD1106 | B15: Van Noort Gassler & Co Rotterdam B.V. | C15: 1108 | D15: Van Noort Gassler & Co. 's-Gravenhage B.V. | E15: VRK | F15: 43774 | G15: 43804 | H15: R190956 | I15: 145.13 | J15: 145.13 | K15: 0 | L15: 0 | M15: 0 | N15: 145.13 | O15: =TODAY()-G15 -> 2366 | P15: Definitief
... A122: RD1106 | B122: Van Noort Gassler & Co Rotterdam B.V. | C122: 1110 | D122: Van Noort Gassler & Co. Haarlem B.V. | E122: VRK | F122: 46097 | G122: 46127 | H122: 102026-0356 | I122: 524.63 | J122: 524.63 | K122: 0 | L122: 524.63 | M122: 0 | N122: 0 | O122: =TODAY()-G122 -> 43 | P122: Concept
A123: RD1106 | B123: Van Noort Gassler & Co Rotterdam B.V. | C123: 1111 | D123: JPA Van Noort Gassler & Co B.V. | E123: BNK | F123: 45903 | G123: 45933 | I123: -90000 | J123: -90000 | K123: 0 | L123: 0 | M123: 0 | N123: -90000 | O123: =TODAY()-G123 -> 237 | P123: Concept
A124: RD1106 | B124: Van Noort Gassler & Co Rotterdam B.V. | C124: 1111 | D124: JPA Van Noort Gassler & Co B.V. | E124: BNK | F124: 46098 | G124: 46128 | I124: -60000 | J124: -60000 | K124: 0 | L124: -60000 | M124: 0 | N124: 0 | O124: =TODAY()-G124 -> 42 | P124: Concept
A125: RD1106 | B125: Van Noort Gassler & Co Rotterdam B.V. | C125: 1111 | D125: JPA Van Noort Gassler & Co B.V. | E125: MEMO | F125: 45835 | G125: 45865 | I125: -218713 | J125: -218713 | K125: 0 | L125: 0 | M125: 0 | N125: -218713 | O125: =TODAY()-G125 -> 305 | P125: Concept
A126: RD1106 | B126: Van Noort Gassler & Co Rotterdam B.V. | C126: 1111 | D126: JPA Van Noort Gassler & Co B.V. | E126: MEMO | F126: 45989 | G126: 46019 | I126: -277509.26 | J126: -277509.26 | K126: 0 | L126: 0 | M126: 0 | N126: -277509.26 | O126: =TODAY()-G126 -> 151 | P126: Concept
A127: RD1106 | B127: Van Noort Gassler & Co Rotterdam B.V. | C127: 1111 | D127: JPA Van Noort Gassler & Co B.V. | E127: VRK | F127: 45448 | G127: 45478 | H127: 102025-0795 | I127: 21600 | J127: 21600 | K127: 0 | L127: 0 | M127: 0 | N127: 21600 | O127: =TODAY()-G127 -> 692 | P127: Concept
A128: RD1106 | B128: Van Noort Gassler & Co Rotterdam B.V. | C128: 1111 | D128: JPA Van Noort Gassler & Co B.V. | E128: VRK | F128: 45461 | G128: 45491 | H128: 2024-0669 | I128: 75957.75 | J128: 45540.44 | K128: 0 | L128: 0 | M128: 0 | N128: 45540.44 | O128: =TODAY()-G128 -> 679 | P128: Concept
A129: RD1106 | B129: Van Noort Gassler & Co Rotterdam B.V. | C129: 1111 | D129: JPA Van Noort Gassler & Co B.V. | E129: VRK | F129: 45470 | G129: 45500 | H129: 2024-0670 | I129: 64595.11 | J129: 64595.11 | K129: 0 | L129: 0 | M129: 0 | N129: 64595.11 | O129: =TODAY()-G129 -> 670 | P129: Concept
A130: RD1106 | B130: Van Noort Gassler & Co Rotterdam B.V. | C130: 1111 | D130: JPA Van Noort Gassler & Co B.V. | E130: VRK | F130: 45475 | G130: 45505 | H130: 2024-0672 | I130: 63218.87 | J130: 63218.87 | K130: 0 | L130: 0 | M130: 0 | N130: 63218.87 | O130: =TODAY()-G130 -> 665 | P130: Concept
A131: RD1106 | B131: Van Noort Gassler & Co Rotterdam B.V. | C131: 1111 | D131: JPA Van Noort Gassler & Co B.V. | E131: VRK | F131: 45482 | G131: 45512 | H131: 2024-0787 | I131: -25155.9 | J131: -25155.9 | K131: 0 | L131: 0 | M131: 0 | N131: -25155.9 | O131: =TODAY()-G131 -> 658 | P131: Concept
A132: RD1106 | B132: Van Noort Gassler & Co Rotterdam B.V. | C132: 1111 | D132: JPA Van Noort Gassler & Co B.V. | E132: VRK | F132: 45482 | G132: 45512 | H132: 2024-0788 | I132: 19602 | J132: 19602 | K132: 0 | L132: 0 | M132: 0 | N132: 19602 | O132: =TODAY()-G132 -> 658 | P132: Concept
A133: RD1106 | B133: Van Noort Gassler & Co Rotterdam B.V. | C133: 1111 | D133: JPA Van Noort Gassler & Co B.V. | E133: VRK | F133: 45506 | G133: 45536 | H133: 2024-0813 | I133: 1815 | J133: 1815 | K133: 0 | L133: 0 | M133: 0 | N133: 1815 | O133: =TODAY()-G133 -> 634 | P133: Concept
A134: RD1106 | B134: Van Noort Gassler & Co Rotterdam B.V. | C134: 1111 | D134: JPA Van Noort Gassler & Co B.V. | E134: VRK | F134: 45509 | G134: 45539 | H134: 2024-0814 | I134: 21845.34 | J134: 21845.34 | K134: 0 | L134: 0 | M134: 0 | N134: 21845.34 | O134: =TODAY()-G134 -> 631 | P134: Concept
A135: RD1106 | B135: Van Noort Gassler & Co Rotterdam B.V. | C135: 1111 | D135: JPA Van Noort Gassler & Co B.V. | E135: VRK | F135: 45509 | G135: 45539 | H135: 2024-0815 | I135: 32365.83 | J135: 32365.83 | K135: 0 | L135: 0 | M135: 0 | N135: 32365.83 | O135: =TODAY()-G135 -> 631 | P135: Concept
A136: RD1106 | B136: Van Noort Gassler & Co Rotterdam B.V. | C136: 1111 | D136: JPA Van Noort Gassler & Co B.V. | E136: VRK | F136: 45519 | G136: 45549 | H136: 2024-0910 | I136: 3539.25 | J136: 3539.25 | K136: 0 | L136: 0 | M136: 0 | N136: 3539.25 | O136: =TODAY()-G136 -> 621 | P136: Concept
A137: RD1106 | B137: Van Noort Gassler & Co Rotterdam B.V. | C137: 1111 | D137: JPA Van Noort Gassler & Co B.V. | E137: VRK | F137: 45530 | G137: 45560 | H137: 2024-0917 | I137: 33215.09 | J137: 33215.09 | K137: 0 | L137: 0 | M137: 0 | N137: 33215.09 | O137: =TODAY()-G137 -> 610 | P137: Concept
A138: RD1106 | B138: Van Noort Gassler & Co Rotterdam B.V. | C138: 1111 | D138: JPA Van Noort Gassler & Co B.V. | E138: VRK | F138: 45530 | G138: 45560 | H138: 2024-0916 | I138: 16694.41 | J138: 16694.41 | K138: 0 | L138: 0 | M138: 0 | N138: 16694.41 | O138: =TODAY()-G138 -> 610 | P138: Concept
... A273: RD1106 | B273: Van Noort Gassler & Co Rotterdam B.V. | C273: 1295 | D273: Patrick van Gils Beheer B.V. | E273: VRK | F273: 46118 | G273: 46148 | H273: 102026-0517 | I273: 79.86 | J273: 79.86 | K273: 79.86 | L273: 0 | M273: 0 | N273: 0 | O273: =TODAY()-G273 -> 22 | P273: Concept
A274: RD1106 | B274: Van Noort Gassler & Co Rotterdam B.V. | C274: 1312 | D274: NEVE Trans B.V. | E274: BNK | F274: 45951 | G274: 45981 | I274: 361.77 | J274: 361.77 | K274: 0 | L274: 0 | M274: 0 | N274: 361.77 | O274: =TODAY()-G274 -> 189 | P274: Concept
A275: RD1106 | B275: Van Noort Gassler & Co Rotterdam B.V. | C275: 1337 | D275: Kraskino Consultants Ltd. | E275: VRK | F275: 44796 | G275: 44826 | H275: 2022-0759 | I275: 1725.26 | J275: 1725.26 | K275: 0 | L275: 0 | M275: 0 | N275: 1725.26 | O275: =TODAY()-G275 -> 1344 | P275: Definitief
A276: RD1106 | B276: Van Noort Gassler & Co Rotterdam B.V. | C276: 1410 | D276: Stichting Studeren/Werken op Maat | E276: BNK | F276: 45699 | G276: 45729 | I276: -242 | J276: -242 | K276: 0 | L276: 0 | M276: 0 | N276: -242 | O276: =TODAY()-G276 -> 441 | P276: Concept
A277: RD1106 | B277: Van Noort Gassler & Co Rotterdam B.V. | C277: 1410 | D277: Stichting Studeren/Werken op Maat | E277: VRK | F277: 45966 | G277: 45996 | H277: 102025-1105 | I277: 9965.26 | J277: 9965.26 | K277: 0 | L277: 0 | M277: 0 | N277: 9965.26 | O277: =TODAY()-G277 -> 174 | P277: Concept
A278: RD1106 | B278: Van Noort Gassler & Co Rotterdam B.V. | C278: 1410 | D278: Stichting Studeren/Werken op Maat | E278: VRK | F278: 46055 | G278: 46085 | H278: 102026-0248 | I278: 3297.25 | J278: 3297.25 | K278: 0 | L278: 0 | M278: 3297.25 | N278: 0 | O278: =TODAY()-G278 -> 85 | P278: Concept
A279: RD1106 | B279: Van Noort Gassler & Co Rotterdam B.V. | C279: 1410 | D279: Stichting Studeren/Werken op Maat | E279: VRK | F279: 46083 | G279: 46113 | H279: 102026-0420 | I279: 3297.25 | J279: 3297.25 | K279: 0 | L279: 3297.25 | M279: 0 | N279: 0 | O279: =TODAY()-G279 -> 57 | P279: Concept
A280: RD1106 | B280: Van Noort Gassler & Co Rotterdam B.V. | C280: 1410 | D280: Stichting Studeren/Werken op Maat | E280: VRK | F280: 46113 | G280: 46143 | H280: 102026-0544 | I280: 3297.25 | J280: 3297.25 | K280: 3297.25 | L280: 0 | M280: 0 | N280: 0 | O280: =TODAY()-G280 -> 27 | P280: Concept
...

Sheet Aging breakdown
E1: Data
A2: NaamDebiteur | B2: Factuurnummer | C2: Vervaldatum | D2: Dagenoud | E2: Sum of Saldo1 | F2: Sum of 030dagen | G2: Sum of 3160dagen | H2: Sum of 6190dagen | I2: Sum of 90dagen
A3: A.J.F. Jansen B.V. | B3: 2025-0240 | C3: 45742 | D3: 428 | E3: 3646.64 | F3: 0 | G3: 0 | H3: 0 | I3: 3646.64
A4: A.J.F. Jansen B.V. Total | E4: 3646.64 | F4: 0 | G4: 0 | H4: 0 | I4: 3646.64
A5: AirFlow Luchtkanalen B.V. | B5: 102026-0361 | C5: 46118 | D5: 52 | E5: 605 | F5: 0 | G5: 605 | H5: 0 | I5: 0
B6: 102026-0501 | C6: 46132 | D6: 38 | E6: 272.25 | F6: 0 | G6: 272.25 | H6: 0 | I6: 0
B7: 102026-0648 | C7: 46162 | D7: 8 | E7: 272.25 | F7: 272.25 | G7: 0 | H7: 0 | I7: 0
B8: 2024-0226 | C8: 45369 | D8: 801 | E8: 666.12 | F8: 0 | G8: 0 | H8: 0 | I8: 666.12
B9: 2025-0330 | C9: 45740 | D9: 430 | E9: 2964.26 | F9: 0 | G9: 0 | H9: 0 | I9: 2964.26
A10: AirFlow Luchtkanalen B.V. Total | E10: 4779.88 | F10: 272.25 | G10: 877.25 | H10: 0 | I10: 3630.38
A11: American Soulfood | B11: 2020-0006 | C11: 43895 | D11: 2275 | E11: 338.8 | F11: 0 | G11: 0 | H11: 0 | I11: 338.8
B12: 2020-0114 | C12: 43895 | D12: 2275 | E12: 338.8 | F12: 0 | G12: 0 | H12: 0 | I12: 338.8
B13: 2020-0213 | E13: 338.8 | F13: 0 | G13: 0 | H13: 0 | I13: 338.8
B14: 2020-0324 | C14: 43958 | D14: 2212 | E14: 338.8 | F14: 0 | G14: 0 | H14: 0 | I14: 338.8
B15: 2020-0483 | C15: 43987 | D15: 2183 | E15: 338.8 | F15: 0 | G15: 0 | H15: 0 | I15: 338.8
B16: 2020-0536 | C16: 44014 | D16: 2156 | E16: 338.8 | F16: 0 | G16: 0 | H16: 0 | I16: 338.8
B17: 2020-0610 | C17: 44043 | D17: 2127 | E17: 338.8 | F17: 0 | G17: 0 | H17: 0 | I17: 338.8
B18: 2020-0718 | C18: 44077 | D18: 2093 | E18: 338.8 | F18: 0 | G18: 0 | H18: 0 | I18: 338.8
B19: 2020-0796 | C19: 44105 | D19: 2065 | E19: 338.8 | F19: 0 | G19: 0 | H19: 0 | I19: 338.8
B20: 2020-0874 | C20: 44140 | D20: 2030 | E20: 338.8 | F20: 0 | G20: 0 | H20: 0 | I20: 338.8
B21: 2020-0986 | C21: 44168 | D21: 2002 | E21: 338.8 | F21: 0 | G21: 0 | H21: 0 | I21: 338.8
B22: 2020-1128 | C22: 44196 | D22: 1974 | E22: 338.8 | F22: 0 | G22: 0 | H22: 0 | I22: 338.8
B23: 2021-0010 | C23: 44233 | D23: 1937 | E23: 338.8 | F23: 0 | G23: 0 | H23: 0 | I23: 338.8
B24: 2022-0553 | C24: 44765 | D24: 1405 | E24: 3025 | F24: 0 | G24: 0 | H24: 0 | I24: 3025
B25: R190024 | C25: 43497 | D25: 2673 | E25: 338.8 | F25: 0 | G25: 0 | H25: 0 | I25: 338.8
... B36: R190995 | C36: 43832 | D36: 2338 | E36: 338.8 | F36: 0 | G36: 0 | H36: 0 | I36: 338.8
A37: American Soulfood Total | E37: 11495 | F37: 0 | G37: 0 | H37: 0 | I37: 11495
A38: Amigo Top B.V. | B38: 102026-0538 | C38: 46140 | D38: 30 | E38: 5749.21 | F38: 5749.21 | G38: 0 | H38: 0 | I38: 0
B39: 2024-1136 | C39: 45579 | D39: 591 | E39: 5407.59 | F39: 0 | G39: 0 | H39: 0 | I39: 5407.59
A40: Amigo Top B.V. Total | E40: 11156.8 | F40: 5749.21 | G40: 0 | H40: 0 | I40: 5407.59
A41: Auroria Pecunia B.V. | B41: 102025-0740 | C41: 45869 | D41: 301 | E41: 653.4 | F41: 0 | G41: 0 | H41: 0 | I41: 653.4
B42: 102025-0984 | C42: 45966 | D42: 204 | E42: 653.4 | F42: 0 | G42: 0 | H42: 0 | I42: 653.4
B43: 102026-0007 | C43: 46060 | D43: 110 | E43: 653.4 | F43: 0 | G43: 0 | H43: 0 | I43: 653.4
B44: 102026-0364 | C44: 46134 | D44: 36 | E44: 707.85 | F44: 0 | G44: 707.85 | H44: 0 | I44: 0
B45: 102026-0442 | C45: 46148 | D45: 22 | E45: 653.4 | F45: 653.4 | G45: 0 | H45: 0 | I45: 0
B46: 2023-1142 | C46: 45267 | D46: 903 | E46: 217.8 | F46: 0 | G46: 0 | H46: 0 | I46: 217.8
B47: 2023-1239 | C47: 45295 | D47: 875 | E47: 217.8 | F47: 0 | G47: 0 | H47: 0 | I47: 217.8
B48: 2024-0049 | C48: 45325 | D48: 845 | E48: 217.8 | F48: 0 | G48: 0 | H48: 0 | I48: 217.8
B49: 2024-0132 | C49: 45357 | D49: 813 | E49: 217.8 | F49: 0 | G49: 0 | H49: 0 | I49: 217.8
B50: 2024-0258 | C50: 45387 | D50: 783 | E50: 217.8 | F50: 0 | G50: 0 | H50: 0 | I50: 217.8
...

Sheet Top20 
A1: Last update: | B1: 46170
A2: High Priority Customers
B3: =SUBTOTAL(9,B5:B124) -> 4381621.8 | C3: =Ouderdomsanalyseperdebiteur!J1075-'Top20 '!B3 -> 1.2107193e-08
A4: NaamDebiteur | B4: Total outstanding balance | C4: Oldest invoice | D4: Days outstanding | E4: Last contact date | F4: Reason not paid (if known) | G4: Owner (finance / account manager) | H4: Remarks | I4: Action Item | K4: Call date | L4: Commitment | M4: Amount | N4: Follow-up Date
A5: JPA Van Noort Gassler & Co B.V. | B5: =SUMIFS(Ouderdomsanalyseperdebiteur!J:J,Ouderdomsanalyseperdebiteur!D:D,'Top20 '!A:A) -> 3729562.3 | C5: 45448 | D5: =TODAY()-C5 -> 722 | I5: JPA
A6: Van Noort Gassler & Co. 's-Gravenhage B.V. | B6: =SUMIFS(Ouderdomsanalyseperdebiteur!J:J,Ouderdomsanalyseperdebiteur!D:D,'Top20 '!A:A) -> 203002.73 | C6: 43690 | D6: =TODAY()-C6 -> 2480 | I6: VNG
A7: Van Noort Gassler & Co. Utrecht B.V. | B7: =SUMIFS(Ouderdomsanalyseperdebiteur!J:J,Ouderdomsanalyseperdebiteur!D:D,'Top20 '!A:A) -> 0 | C7: 46076 | D7: =TODAY()-C7 -> 94 | I7: VNG
A8: Van Noort Gassler & Co. Haarlem B.V. | B8: =SUMIFS(Ouderdomsanalyseperdebiteur!J:J,Ouderdomsanalyseperdebiteur!D:D,'Top20 '!A:A) -> 18214.83 | C8: 44943 | D8: =TODAY()-C8 -> 1227 | I8: VNG
A9: Pijnex Internationationaal Transport | B9: =SUMIFS(Ouderdomsanalyseperdebiteur!J:J,Ouderdomsanalyseperdebiteur!D:D,'Top20 '!A:A) -> 44425 | C9: 45684 | D9: =TODAY()-C9 -> 486 | G9: Quirin Nieuwenhuizen | I9: Payment agreement set-up - we need to update the monthly payment from 1k to 3k
A10: R.A.U. Juchter van Bergen Quast B.V. | B10: =SUMIFS(Ouderdomsanalyseperdebiteur!J:J,Ouderdomsanalyseperdebiteur!D:D,'Top20 '!A:A) -> 40270.76 | C10: 43098 | D10: =TODAY()-C10 -> 3072 | G10: Laurens Nijssen | H10: No action needed
A11: LUKOIL International Upstream Holdings B.V. | B11: =SUMIFS(Ouderdomsanalyseperdebiteur!J:J,Ouderdomsanalyseperdebiteur!D:D,'Top20 '!A:A) -> 28645.24 | C11: 46009 | D11: =TODAY()-C11 -> 161 | G11: Shaira Castillo-Vierneza | I11: to check if payment is updated
A12: Vincent van der Weijden Holding B.V. | B12: =SUMIFS(Ouderdomsanalyseperdebiteur!J:J,Ouderdomsanalyseperdebiteur!D:D,'Top20 '!A:A) -> 23347.62 | C12: 44412 | D12: =TODAY()-C12 -> 1758 | G12: Quirin Nieuwenhuizen | H12: Payment agreement set up | I12: to check if payment is updated
A13: Lewis Fashion Group B.V. | B13: =SUMIFS(Ouderdomsanalyseperdebiteur!J:J,Ouderdomsanalyseperdebiteur!D:D,'Top20 '!A:A) -> 23075.47 | C13: 45450 | D13: =TODAY()-C13 -> 720 | G13: Quirin Nieuwenhuizen | H13: Payment agreement set up | I13: to check if payment is updated
A14: Stichting Studeren/Werken op Maat | B14: =SUMIFS(Ouderdomsanalyseperdebiteur!J:J,Ouderdomsanalyseperdebiteur!D:D,'Top20 '!A:A) -> 20189.76 | C14: 45699 | D14: =TODAY()-C14 -> 471 | G14: Betty Kieboom | I14: Email - Nice email
A15: Duckies B.V. | B15: =SUMIFS(Ouderdomsanalyseperdebiteur!J:J,Ouderdomsanalyseperdebiteur!D:D,'Top20 '!A:A) -> 18595.52 | C15: 45726 | D15: =TODAY()-C15 -> 444 | G15: Quirin Nieuwenhuizen | I15: Email - Nice email
A16: Elstgeest Ventures B.V. | B16: =SUMIFS(Ouderdomsanalyseperdebiteur!J:J,Ouderdomsanalyseperdebiteur!D:D,'Top20 '!A:A) -> 12552.48 | C16: 45691 | D16: =TODAY()-C16 -> 479 | G16: Quirin Nieuwenhuizen | I16: Email - Strickt email
A17: Autodemontagebedrijf Th. van Gils B.V. | B17: =SUMIFS(Ouderdomsanalyseperdebiteur!J:J,Ouderdomsanalyseperdebiteur!D:D,'Top20 '!A:A) -> 12162.56 | C17: 46104 | D17: =TODAY()-C17 -> 66 | G17: Betty Kieboom | I17: Email - Standard
A18: Rijks Investments B.V. | B18: =SUMIFS(Ouderdomsanalyseperdebiteur!J:J,Ouderdomsanalyseperdebiteur!D:D,'Top20 '!A:A) -> 12014.16 | C18: 44378 | D18: =TODAY()-C18 -> 1792 | G18: Edwin Mafficioli del Castelletto | I18: Deurwaarder
A19: G8plus B.V. | B19: =SUMIFS(Ouderdomsanalyseperdebiteur!J:J,Ouderdomsanalyseperdebiteur!D:D,'Top20 '!A:A) -> 11753.15 | C19: 42768 | D19: =TODAY()-C19 -> 3402 | G19: Laurens Nijssen | I19: Deurwaarder
A20: American Soulfood | B20: =SUMIFS(Ouderdomsanalyseperdebiteur!J:J,Ouderdomsanalyseperdebiteur!D:D,'Top20 '!A:A) -> 11495 | C20: 43467 | D20: =TODAY()-C20 -> 2703 | G20: Betty Kieboom | I20: Deurwaarder BE - navragen
A21: Serviceheroes B.V. | B21: =SUMIFS(Ouderdomsanalyseperdebiteur!J:J,Ouderdomsanalyseperdebiteur!D:D,'Top20 '!A:A) -> 11187.06 | C21: 45726 | D21: =TODAY()-C21 -> 444 | G21: Edwin Mafficioli del Castelletto | I21: Email - Standard
A22: Amigo Top B.V. | B22: =SUMIFS(Ouderdomsanalyseperdebiteur!J:J,Ouderdomsanalyseperdebiteur!D:D,'Top20 '!A:A) -> 11156.8 | C22: 45565 | D22: =TODAY()-C22 -> 605 | G22: Edwin Mafficioli del Castelletto | H22: No action needed; No reminder needed.
A23: TOFF concept | B23: =SUMIFS(Ouderdomsanalyseperdebiteur!J:J,Ouderdomsanalyseperdebiteur!D:D,'Top20 '!A:A) -> 9764.14 | C23: 44927 | D23: =TODAY()-C23 -> 1243 | G23: Quirin Nieuwenhuizen | I23: Payment Agreement
A24: Autobedrijf Tinga & Zn | B24: =SUMIFS(Ouderdomsanalyseperdebiteur!J:J,Ouderdomsanalyseperdebiteur!D:D,'Top20 '!A:A) -> 9075 | C24: 45856 | D24: =TODAY()-C24 -> 314 | G24: Edwin Mafficioli del Castelletto | I24: Email - Standard
A25: Hans van Rooij Consultancy | B25: =SUMIFS(Ouderdomsanalyseperdebiteur!J:J,Ouderdomsanalyseperdebiteur!D:D,'Top20 '!A:A) -> 9075 | C25: 44537 | D25: =TODAY()-C25 -> 1633 | G25: Laura Vet-van Waart | I25: To Edwin
A26: Heron Groep B.V. | B26: =SUMIFS(Ouderdomsanalyseperdebiteur!J:J,Ouderdomsanalyseperdebiteur!D:D,'Top20 '!A:A) -> 8205.38 | C26: 45672 | D26: =TODAY()-C26 -> 498 | G26: Betty Kieboom | I26: Email - Standard
A27: Auroria Pecunia B.V. | B27: =SUMIFS(Ouderdomsanalyseperdebiteur!J:J,Ouderdomsanalyseperdebiteur!D:D,'Top20 '!A:A) -> 7979.95 | C27: 45237 | D27: =TODAY()-C27 -> 933 | G27: Quirin Nieuwenhuizen | I27: Email - Nice email
A28: M.P. Polderdijk Holding B.V. | B28: =SUMIFS(Ouderdomsanalyseperdebiteur!J:J,Ouderdomsanalyseperdebiteur!D:D,'Top20 '!A:A) -> 6322.25 | C28: 43467 | D28: =TODAY()-C28 -> 2703 | G28: Betty Kieboom | I28: Deurwaarder BE - navragen
A29: Interlex | B29: =SUMIFS(Ouderdomsanalyseperdebiteur!J:J,Ouderdomsanalyseperdebiteur!D:D,'Top20 '!A:A) -> 5915.51 | C29: 43846 | D29: =TODAY()-C29 -> 2324 | G29: Edwin Mafficioli del Castelletto
A30: Levels Diagnostics B.V. | B30: =SUMIFS(Ouderdomsanalyseperdebiteur!J:J,Ouderdomsanalyseperdebiteur!D:D,'Top20 '!A:A) -> 5747.5 | C30: 46125 | D30: =TODAY()-C30 -> 45 | G30: Edwin Mafficioli del Castelletto | I30: Email - Nice email
A31: Coöperatieve Vijftientien U.A. | B31: =SUMIFS(Ouderdomsanalyseperdebiteur!J:J,Ouderdomsanalyseperdebiteur!D:D,'Top20 '!A:A) -> 4962.01 | C31: 45789 | D31: =TODAY()-C31 -> 381 | G31: Edwin Mafficioli del Castelletto
A32: Deelman Timmerwerken B.V. | B32: =SUMIFS(Ouderdomsanalyseperdebiteur!J:J,Ouderdomsanalyseperdebiteur!D:D,'Top20 '!A:A) -> 4900.5 | C32: 45782 | D32: =TODAY()-C32 -> 388 | G32: Quirin Nieuwenhuizen | I32: Email - Nice email
A33: AirFlow Luchtkanalen B.V. | B33: =SUMIFS(Ouderdomsanalyseperdebiteur!J:J,Ouderdomsanalyseperdebiteur!D:D,'Top20 '!A:A) -> 4779.88 | C33: 45355 | D33: =TODAY()-C33 -> 815 | G33: Quirin Nieuwenhuizen | I33: Email - Nice email
A34: Meydanim Den Haag B.V. | B34: =SUMIFS(Ouderdomsanalyseperdebiteur!J:J,Ouderdomsanalyseperdebiteur!D:D,'Top20 '!A:A) -> 4737.58 | C34: 43774 | D34: =TODAY()-C34 -> 2396 | G34: Betty Kieboom | I34: Deurwaarder
A35: Ray Consultancy B.V. | B35: =SUMIFS(Ouderdomsanalyseperdebiteur!J:J,Ouderdomsanalyseperdebiteur!D:D,'Top20 '!A:A) -> 4640.37 | C35: 43679 | D35: =TODAY()-C35 -> 2491 | G35: Laurens Nijssen | I35: Deurwaarder
A36: Stichting Zwitserse Kamer van Koophandel in Nederland | B36: =SUMIFS(Ouderdomsanalyseperdebiteur!J:J,Ouderdomsanalyseperdebiteur!D:D,'Top20 '!A:A) -> 4537.5 | C36: 44886 | D36: =TODAY()-C36 -> 1284 | G36: Laura Vet-van Waart
A37: RMA Loodgieter | B37: =SUMIFS(Ouderdomsanalyseperdebiteur!J:J,Ouderdomsanalyseperdebiteur!D:D,'Top20 '!A:A) -> 3682.64 | C37: 45481 | D37: =TODAY()-C37 -> 689 | G37: Quirin Nieuwenhuizen | I37: Deurwaarder
A38: A.J.F. Jansen B.V. | B38: =SUMIFS(Ouderdomsanalyseperdebiteur!J:J,Ouderdomsanalyseperdebiteur!D:D,'Top20 '!A:A) -> 3646.64 | C38: 45712 | D38: =TODAY()-C38 -> 458 | G38: Betty Kieboom | I38: Email - Nice email
A39: Respublica B.V. | B39: =SUMIFS(Ouderdomsanalyseperdebiteur!J:J,Ouderdomsanalyseperdebiteur!D:D,'Top20 '!A:A) -> 3584.63 | C39: 45957 | D39: =TODAY()-C39 -> 213 | G39: Edwin Mafficioli del Castelletto | I39: to deurwaarder
A40: RJD Infra | B40: =SUMIFS(Ouderdomsanalyseperdebiteur!J:J,Ouderdomsanalyseperdebiteur!D:D,'Top20 '!A:A) -> 3575.55 | C40: 45048 | D40: =TODAY()-C40 -> 1122 | G40: Nowshin Jahan | I40: Deurwaarder
...

Sheet Action item Summary
B1: Row Labels | C1: Count of NaamDebiteur | D1: Sum of Total outstanding balance | F1: Sum of Total outstanding balance
B2: Deurwaarder | C2: 24 | D2: 59985.01 | F2: Owner (finance / account manager) | G2: Action Item | H2: Total
B3: Grand Total | C3: 24 | D3: 59985.01 | F3: Betty Kieboom | G3: Deurwaarder | H3: 16279.77
G4: Deurwaarder BE - navragen | H4: 17817.25
G5: Email - Nice email | H5: 23836.4
G6: Email - Standard | H6: 20367.94
G7: to deurwaarder | H7: 2078.43
G8: (blank) | H8: 10236.72
F9: Betty Kieboom Total | H9: 90616.51
F10: Dave Nahar | G10: (blank) | H10: 361.77
F11: Dave Nahar Total | H11: 361.77
F12: Edwin Mafficioli del Castelletto | G12: Deurwaarder | H12: 14484.07
G13: Email - Nice email | H13: 5747.5
G14: Email - Standard | H14: 20262.06
G15: to deurwaarder | H15: 3584.63
G16: (blank) | H16: 31665.17
F17: Edwin Mafficioli del Castelletto Total | H17: 75743.43
F18: for checking | G18: Deurwaarder | H18: 3306.76
G19: (blank) | H19: 3265.81
F20: for checking Total | H20: 6572.57
F21: Laura Vet-van Waart | G21: Deurwaarder | H21: 453.75
G22: To Edwin | H22: 9075
G23: (blank) | H23: 12560.14
F24: Laura Vet-van Waart Total | H24: 22088.89
F25: Laurens Nijssen | G25: Deurwaarder | H25: 16575.02
G26: (blank) | H26: 40270.76
F27: Laurens Nijssen Total | H27: 56845.78
F28: Marcel Meerman | G28: (blank) | H28: -36905
F29: Marcel Meerman Total | H29: -36905
F30: Nowshin Jahan | G30: Deurwaarder | H30: 3575.55
F31: Nowshin Jahan Total | H31: 3575.55
F32: Quirin Nieuwenhuizen | G32: Deurwaarder | H32: 5310.09
G33: Email - Nice email | H33: 36255.85
G34: Email - Strickt email | H34: 12552.48
G35: Payment Agreement | H35: 9764.14
G36: Payment agreement set-up - we need to update the monthly payment from 1k to 3k | H36: 44425
G37: to check if payment is updated | H37: 46423.09
G38: (blank) | H38: 28566.52
F39: Quirin Nieuwenhuizen Total | H39: 183297.17
F40: Shaira Castillo-Vierneza | G40: to check if payment is updated | H40: 28645.24
...
